

<mujoco model="sparky">
  <compiler angle="radian" meshdir="meshes/" autolimits="true"/>

  <default>
    <default class="sparky">
      <geom friction="0.6" margin="0.001"/>
      <joint axis="0 1 0" damping="2" armature="0.01" frictionloss="0.2"/>
      <position kp="80" forcerange="-25 25"/>
      <default class="abductor">
        <joint axis="1 0 0" damping="1" range="-1 1"/>
        <position ctrlrange="-1.57 1.57"/>
      </default>
      <default class="hip">
        <joint range="-1.57 1.57"/>
        <position ctrlrange="-1.57 1.57"/>
      </default>
      <default class="knee">
        <joint range="-1.57 1.57"/>
        <position ctrlrange="-3 3"/>
      </default>
    </default>
  </default>

  <asset>
    <mesh name="base_link" file="base_link.stl" scale="0.001 0.001 0.001"/>
    <mesh name="front_right_abductor1" file="front_right_abductor1.stl" scale="0.001 0.001 0.001"/>
    <mesh name="front_left_abductor1" file="front_left_abductor1.stl" scale="0.001 0.001 0.001"/>
    <mesh name="back_right_abductor1" file="back_right_abductor1.stl" scale="0.001 0.001 0.001"/>
    <mesh name="back_left_abductor1" file="back_left_abductor1.stl" scale="0.001 0.001 0.001"/>
    <mesh name="front_right_upper_leg1" file="front_right_upper_leg1.stl" scale="0.001 0.001 0.001"/>
    <mesh name="back_left_upper_leg1" file="back_left_upper_leg1.stl" scale="0.001 0.001 0.001"/>
    <mesh name="front_left_upper_leg1" file="front_left_upper_leg1.stl" scale="0.001 0.001 0.001"/>
    <mesh name="back_right_upper_leg1" file="back_right_upper_leg1.stl" scale="0.001 0.001 0.001"/>
    <mesh name="front_right_lower_leg1" file="front_right_lower_leg1.stl" scale="0.001 0.001 0.001"/>
    <mesh name="back_right_lower_leg1" file="back_right_lower_leg1.stl" scale="0.001 0.001 0.001"/>
    <mesh name="front_left_lower_leg1" file="front_left_lower_leg1.stl" scale="0.001 0.001 0.001"/>
    <mesh name="back_left_lower_leg1" file="back_left_lower_leg1.stl" scale="0.001 0.001 0.001"/>
  </asset>
  
  <worldbody>
    <body name="trunk" pos="0 0 0.01" quat= "1 1 0 0" childclass="sparky">
      <freejoint/>
      <geom type="mesh" contype="0" conaffinity="0" group="1" density="0" mesh="base_link"/>
      <geom type="mesh" mesh="base_link"/>
      <body name="front_right_abductor1" pos="0.0635 0.467668 0.162569">
        <inertial pos="-0.00132483 -0.000708044 0.054912" quat="0.999741 0.011413 -0.00793461 -0.0180434" mass="0.445618" diaginertia="0.000684714 0.000488292 0.000363042"/>
        <joint class="abductor" name="FL_abductor" pos="0 0 0" axis="0 0 1"/>
        <geom pos="-0.0635 -0.467668 -0.162569" type="mesh" contype="0" conaffinity="0" group="1" density="0" mesh="front_right_abductor1"/>
        <geom pos="-0.0635 -0.467668 -0.162569" type="mesh" mesh="front_right_abductor1"/>
        <body name="front_left_upper_leg1" pos="0.0254 0 0.0635">
          <inertial pos="0.0481477 -0.0298107 0.000192477" quat="0.700869 0.706971 0.043841 0.0839781" mass="0.744888" diaginertia="0.00310845 0.00304062 0.000635321"/>
          <joint class="hip" name="FL_hip" pos="0 0 0" axis="-1 0 0"/>
          <geom pos="-0.0889 -0.467668 -0.226069" type="mesh" contype="0" conaffinity="0" group="1" density="0" mesh="front_left_upper_leg1"/>
          <geom pos="-0.0889 -0.467668 -0.226069" type="mesh" mesh="front_left_upper_leg1"/>
          <body name="front_left_lower_leg1" pos="0.068262 -0.22225 0">
            <inertial pos="-0.000610027 -0.100884 3.1979e-07" quat="0.707102 0.707102 -0.00255178 -0.00255178" mass="0.0866073" diaginertia="0.000811444 0.000805933 1.15493e-05"/>
            <joint class="knee" name="FL_knee" pos="0 0 0" axis="-1 0 0"/>
            <geom pos="-0.157162 -0.245418 -0.226069" type="mesh" contype="0" conaffinity="0" group="1" density="0" mesh="front_left_lower_leg1"/>
            <geom pos="-0.157162 -0.245418 -0.226069" type="mesh" mesh="front_left_lower_leg1"/>
          </body>
        </body>
      </body>
      <body name="front_left_abductor1" pos="-0.0635 0.467668 0.162569">
        <inertial pos="0.00132483 -0.000708044 0.054912" quat="0.999741 0.011413 0.00793461 0.0180434" mass="0.445618" diaginertia="0.000684714 0.000488292 0.000363042"/>
        <joint class="abductor" name="FR_abductor" pos="0 0 0" axis="0 0 -1"/>
        <geom pos="0.0635 -0.467668 -0.162569" type="mesh" contype="0" conaffinity="0" group="1" density="0" mesh="front_left_abductor1"/>
        <geom pos="0.0635 -0.467668 -0.162569" type="mesh" mesh="front_left_abductor1"/>
        <body name="front_right_upper_leg1" pos="-0.0254 0 0.0635">
          <inertial pos="-0.0481477 -0.0298107 0.000192481" quat="0.700869 0.706971 -0.0438411 -0.083978" mass="0.744888" diaginertia="0.00310845 0.00304062 0.000635321"/>
          <joint class="hip" name="FR_hip" pos="0 0 0" axis="-1 0 0"/>
          <geom pos="0.0889 -0.467668 -0.226069" type="mesh" contype="0" conaffinity="0" group="1" density="0" mesh="front_right_upper_leg1"/>
          <geom pos="0.0889 -0.467668 -0.226069" type="mesh" mesh="front_right_upper_leg1"/>
          <body name="front_right_lower_leg1" pos="-0.068263 -0.22225 0">
            <inertial pos="0.00061119 -0.100883 2.61096e-07" quat="0.707102 0.707102 0.00255243 0.00255243" mass="0.086607" diaginertia="0.000811441 0.00080593 1.1549e-05"/>
            <joint class="knee" name="FR_knee" pos="0 0 0" axis="-1 0 0"/>
            <geom pos="0.157163 -0.245418 -0.226069" type="mesh" contype="0" conaffinity="0" group="1" density="0" mesh="front_right_lower_leg1"/>
            <geom pos="0.157163 -0.245418 -0.226069" type="mesh" mesh="front_right_lower_leg1"/>
          </body>
        </body>
      </body>
      <body name="back_right_abductor1" pos="0.0635 0.467668 -0.158106">
        <inertial pos="-0.00132483 -0.000708044 -0.0549114" quat="0.999741 -0.011413 0.00793461 -0.0180434" mass="0.445618" diaginertia="0.000684714 0.000488292 0.000363042"/>
        <joint class="abductor" name="BL_abductor" pos="0 0 0" axis="0 0 1"/>
        <geom pos="-0.0635 -0.467668 0.158106" type="mesh" contype="0" conaffinity="0" group="1" density="0" mesh="back_right_abductor1"/>
        <geom pos="-0.0635 -0.467668 0.158106" type="mesh" mesh="back_right_abductor1"/>
        <body name="back_left_upper_leg1" pos="0.0254 0 -0.0635">
          <inertial pos="0.0481477 -0.0298107 -0.000191848" quat="0.706971 0.700869 0.083978 0.0438411" mass="0.744888" diaginertia="0.00310845 0.00304062 0.000635321"/>
          <joint class="hip" name="BL_hip" pos="0 0 0" axis="1 0 0"/>
          <geom pos="-0.0889 -0.467668 0.221606" type="mesh" contype="0" conaffinity="0" group="1" density="0" mesh="back_left_upper_leg1"/>
          <geom pos="-0.0889 -0.467668 0.221606" type="mesh" mesh="back_left_upper_leg1"/>
          <body name="back_left_lower_leg1" pos="0.068262 -0.22225 0">
            <inertial pos="-0.000610027 -0.100884 3.1979e-07" quat="0.707102 0.707102 -0.00255178 -0.00255178" mass="0.0866073" diaginertia="0.000811444 0.000805933 1.15493e-05"/>
            <joint class="knee" name="BL_knee" pos="0 0 0" axis="1 0 0"/>
            <geom pos="-0.157162 -0.245418 0.221606" type="mesh" contype="0" conaffinity="0" group="1" density="0" mesh="back_left_lower_leg1"/>
            <geom pos="-0.157162 -0.245418 0.221606" type="mesh" mesh="back_left_lower_leg1"/>
          </body>
        </body>
      </body>
      <body name="back_left_abductor1" pos="-0.0635 0.467668 -0.158106">
        <inertial pos="0.00132483 -0.000708044 -0.0549114" quat="0.999741 -0.011413 -0.00793461 0.0180434" mass="0.445618" diaginertia="0.000684714 0.000488292 0.000363042"/>
        <joint class="abductor" name="BR_abductor" pos="0 0 0" axis="0 0 -1"/>
        <geom pos="0.0635 -0.467668 0.158106" type="mesh" contype="0" conaffinity="0" group="1" density="0" mesh="back_left_abductor1"/>
        <geom pos="0.0635 -0.467668 0.158106" type="mesh" mesh="back_left_abductor1"/>
        <body name="back_right_upper_leg1" pos="-0.0254 0 -0.0635">
          <inertial pos="-0.0481477 -0.0298107 -0.000191844" quat="0.706971 0.700869 -0.0839781 -0.043841" mass="0.744888" diaginertia="0.00310845 0.00304062 0.000635321"/>
          <joint class="hip" name="BR_hip" pos="0 0 0" axis="1 0 0"/>
          <geom pos="0.0889 -0.467668 0.221606" type="mesh" contype="0" conaffinity="0" group="1" density="0" mesh="back_right_upper_leg1"/>
          <geom pos="0.0889 -0.467668 0.221606" type="mesh" mesh="back_right_upper_leg1"/>
          <body name="back_right_lower_leg1" pos="-0.068263 -0.22225 0">
            <inertial pos="0.00061119 -0.100883 2.61096e-07" quat="0.707102 0.707102 0.00255243 0.00255243" mass="0.086607" diaginertia="0.000811441 0.00080593 1.1549e-05"/>
            <joint class="knee" name="BR_knee" pos="0 0 0" axis="1 0 0"/>
            <geom pos="0.157163 -0.245418 0.221606" type="mesh" contype="0" conaffinity="0" group="1" density="0" mesh="back_right_lower_leg1"/>
            <geom pos="0.157163 -0.245418 0.221606" type="mesh" mesh="back_right_lower_leg1"/>
          </body>
        </body>
      </body>
    </body>
  </worldbody>

  <actuator>
    <position class="abductor" name="FL_abductor" joint="FL_abductor"/>
    <position class="hip" name="FL_hip" joint="FL_hip"/>
    <position class="knee" name="FL_knee" joint="FL_knee" gear="1.5"/>
    <position class="abductor" name="FR_abductor" joint="FR_abductor"/>
    <position class="hip" name="FR_hip" joint="FR_hip"/>
    <position class="knee" name="FR_knee" joint="FR_knee" gear="1.5"/>
    <position class="abductor" name="BL_abductor" joint="BL_abductor"/>
    <position class="hip" name="BL_hip" joint="BL_hip"/>
    <position class="knee" name="BL_knee" joint="BL_knee" gear="1.5"/>
    <position class="abductor" name="BR_abductor" joint="BR_abductor"/>
    <position class="hip" name="BR_hip" joint="BR_hip"/>
    <position class="knee" name="BR_knee" joint="BR_knee" gear="1.5"/>
  </actuator>

  <contact>
    <exclude body1="trunk" body2="front_left_upper_leg1"/>
    <exclude body1="trunk" body2="front_right_upper_leg1"/>
    <exclude body1="trunk" body2="back_left_upper_leg1"/>
    <exclude body1="trunk" body2="back_right_upper_leg1"/>
  </contact>

</mujoco>
